<?xml version="1.0"?>
<robot xmlns:xacro="http://www.ros.org/wiki/xacro">
    <xacro:macro name="robot_wheel" params="prefix">
        <link name="${prefix}_wheel">
            <inertial>
                <origin
                    xyz="0.0030946 4.78250032638821E-11 0.053305"
                    rpy="0 0 0" />
                <mass
                    value="47.873" />
                <inertia
                    ixx="0.774276574699151"
                    ixy="-1.03781944357671E-10"
                    ixz="0.00763014265820928"
                    iyy="1.64933255189991"
                    iyz="1.09578155845563E-12"
                    izz="2.1239326987473" />
            </inertial>
            <visual>
                <origin
                    xyz="0 0 0"
                    rpy="1.5707963267949 0 0" />
                <geometry>
                    <mesh filename="package://robot_description/meshes/wheel.stl" />
                </geometry>
                <material
                    name="">
                    <color
                    rgba="0.79216 0.81961 0.93333 1" />
                </material>
            </visual>
            <collision>
                <origin
                    xyz="0 0 0"
                    rpy="1.5707963267949 0 0" />
                <geometry>
                    <mesh filename="package://robot_description/meshes/robot_base.stl" />
                </geometry>
            </collision>
        </link>
    </xacro:macro>


    <xacro:macro name="wheel_joint" params="prefix origin">
        <joint name="${prefix}_wheel_joint" type="continuous">
            <axis xyz="0 1 0"/>
            <parent link="base_link"/>
            <child link="${prefix}_wheel"/>
            <origin rpy="0 0 0" xyz="${origin}"/>
        </joint>
    </xacro:macro>


    <xacro:macro name="base_transmission" params="prefix ">
        <transmission name="${prefix}_wheel_trans" type="SimpleTransmission">
            <type>transmission_interface/SimpleTransmission</type>
            <actuator name="${prefix}_wheel_motor">
                <hardwareInterface>hardware_interface/VelocityJointInterface</hardwareInterface>
                <mechanicalReduction>1</mechanicalReduction>
            </actuator>
            <joint name="${prefix}_wheel_joint">
                <hardwareInterface>hardware_interface/VelocityJointInterface</hardwareInterface>
            </joint>
        </transmission>
    </xacro:macro>


</robot>